Watching for file changes with StatReloader
Exception in thread django-main-thread:
Traceback (most recent call last):
  File "/Library/Frameworks/Python.framework/Versions/3.11/lib/python3.11/threading.py", line 1045, in _bootstrap_inner
    self.run()
  File "/Library/Frameworks/Python.framework/Versions/3.11/lib/python3.11/threading.py", line 982, in run
    self._target(*self._args, **self._kwargs)
  File "/Library/Frameworks/Python.framework/Versions/3.11/lib/python3.11/site-packages/django/utils/autoreload.py", line 64, in wrapper
    fn(*args, **kwargs)
  File "/Library/Frameworks/Python.framework/Versions/3.11/lib/python3.11/site-packages/django/core/management/commands/runserver.py", line 134, in inner_run
    self.check(**check_kwargs)
  File "/Library/Frameworks/Python.framework/Versions/3.11/lib/python3.11/site-packages/django/core/management/base.py", line 492, in check
    all_issues = checks.run_checks(
                 ^^^^^^^^^^^^^^^^^^
  File "/Library/Frameworks/Python.framework/Versions/3.11/lib/python3.11/site-packages/django/core/checks/registry.py", line 89, in run_checks
    new_errors = check(app_configs=app_configs, databases=databases)
                 ^^^^^^^^^^^^^^^^^^^^^^^^^^^^^^^^^^^^^^^^^^^^^^^^^^^
  File "/Library/Frameworks/Python.framework/Versions/3.11/lib/python3.11/site-packages/django/core/checks/urls.py", line 136, in check_custom_error_handlers
    handler = resolver.resolve_error_handler(status_code)
              ^^^^^^^^^^^^^^^^^^^^^^^^^^^^^^^^^^^^^^^^^^^
  File "/Library/Frameworks/Python.framework/Versions/3.11/lib/python3.11/site-packages/django/urls/resolvers.py", line 732, in resolve_error_handler
    callback = getattr(self.urlconf_module, "handler%s" % view_type, None)
                       ^^^^^^^^^^^^^^^^^^^
  File "/Library/Frameworks/Python.framework/Versions/3.11/lib/python3.11/site-packages/django/utils/functional.py", line 47, in __get__
    res = instance.__dict__[self.name] = self.func(instance)
                                         ^^^^^^^^^^^^^^^^^^^
  File "/Library/Frameworks/Python.framework/Versions/3.11/lib/python3.11/site-packages/django/urls/resolvers.py", line 711, in urlconf_module
    return import_module(self.urlconf_name)
           ^^^^^^^^^^^^^^^^^^^^^^^^^^^^^^^^
  File "/Library/Frameworks/Python.framework/Versions/3.11/lib/python3.11/importlib/__init__.py", line 126, in import_module
    return _bootstrap._gcd_import(name[level:], package, level)
           ^^^^^^^^^^^^^^^^^^^^^^^^^^^^^^^^^^^^^^^^^^^^^^^^^^^^
  File "<frozen importlib._bootstrap>", line 1204, in _gcd_import
  File "<frozen importlib._bootstrap>", line 1176, in _find_and_load
  File "<frozen importlib._bootstrap>", line 1147, in _find_and_load_unlocked
  File "<frozen importlib._bootstrap>", line 690, in _load_unlocked
  File "<frozen importlib._bootstrap_external>", line 940, in exec_module
  File "<frozen importlib._bootstrap>", line 241, in _call_with_frames_removed
  File "/Users/boussastevejunior/Desktop/Dev/Personal/FiberMap/FiberMap/FiberMap/urls.py", line 13, in <module>
    path('api/', include('api.urls')),
                 ^^^^^^^^^^^^^^^^^^^
  File "/Library/Frameworks/Python.framework/Versions/3.11/lib/python3.11/site-packages/django/urls/conf.py", line 39, in include
    urlconf_module = import_module(urlconf_module)
                     ^^^^^^^^^^^^^^^^^^^^^^^^^^^^^
  File "/Library/Frameworks/Python.framework/Versions/3.11/lib/python3.11/importlib/__init__.py", line 126, in import_module
    return _bootstrap._gcd_import(name[level:], package, level)
           ^^^^^^^^^^^^^^^^^^^^^^^^^^^^^^^^^^^^^^^^^^^^^^^^^^^^
  File "<frozen importlib._bootstrap>", line 1204, in _gcd_import
  File "<frozen importlib._bootstrap>", line 1176, in _find_and_load
  File "<frozen importlib._bootstrap>", line 1147, in _find_and_load_unlocked
  File "<frozen importlib._bootstrap>", line 690, in _load_unlocked
  File "<frozen importlib._bootstrap_external>", line 940, in exec_module
  File "<frozen importlib._bootstrap>", line 241, in _call_with_frames_removed
  File "/Users/boussastevejunior/Desktop/Dev/Personal/FiberMap/FiberMap/api/urls.py", line 51, in <module>
    path('hello/', views.hello, name='api-hello'),
                   ^^^^^^^^^^^
AttributeError: module 'api.views' has no attribute 'hello'
/Users/boussastevejunior/Desktop/Dev/Personal/FiberMap/FiberMap/api/urls.py changed, reloading.
Performing system checks...

Watching for file changes with StatReloader
Exception in thread django-main-thread:
Traceback (most recent call last):
  File "/Library/Frameworks/Python.framework/Versions/3.11/lib/python3.11/site-packages/django/core/checks/urls.py", line 136, in check_custom_error_handlers
    handler = resolver.resolve_error_handler(status_code)
              ^^^^^^^^^^^^^^^^^^^^^^^^^^^^^^^^^^^^^^^^^^^
  File "/Library/Frameworks/Python.framework/Versions/3.11/lib/python3.11/site-packages/django/urls/resolvers.py", line 732, in resolve_error_handler
    callback = getattr(self.urlconf_module, "handler%s" % view_type, None)
                       ^^^^^^^^^^^^^^^^^^^
  File "/Library/Frameworks/Python.framework/Versions/3.11/lib/python3.11/site-packages/django/utils/functional.py", line 47, in __get__
    res = instance.__dict__[self.name] = self.func(instance)
                                         ^^^^^^^^^^^^^^^^^^^
  File "/Library/Frameworks/Python.framework/Versions/3.11/lib/python3.11/site-packages/django/urls/resolvers.py", line 711, in urlconf_module
    return import_module(self.urlconf_name)
           ^^^^^^^^^^^^^^^^^^^^^^^^^^^^^^^^
  File "/Library/Frameworks/Python.framework/Versions/3.11/lib/python3.11/importlib/__init__.py", line 126, in import_module
    return _bootstrap._gcd_import(name[level:], package, level)
           ^^^^^^^^^^^^^^^^^^^^^^^^^^^^^^^^^^^^^^^^^^^^^^^^^^^^
  File "<frozen importlib._bootstrap>", line 1204, in _gcd_import
  File "<frozen importlib._bootstrap>", line 1176, in _find_and_load
  File "<frozen importlib._bootstrap>", line 1147, in _find_and_load_unlocked
  File "<frozen importlib._bootstrap>", line 690, in _load_unlocked
  File "<frozen importlib._bootstrap_external>", line 940, in exec_module
  File "<frozen importlib._bootstrap>", line 241, in _call_with_frames_removed
  File "/Users/boussastevejunior/Desktop/Dev/Personal/FiberMap/FiberMap/FiberMap/urls.py", line 13, in <module>
    path('api/', include('api.urls')),
                 ^^^^^^^^^^^^^^^^^^^
  File "/Library/Frameworks/Python.framework/Versions/3.11/lib/python3.11/site-packages/django/urls/conf.py", line 39, in include
    urlconf_module = import_module(urlconf_module)
                     ^^^^^^^^^^^^^^^^^^^^^^^^^^^^^
  File "/Library/Frameworks/Python.framework/Versions/3.11/lib/python3.11/importlib/__init__.py", line 126, in import_module
    return _bootstrap._gcd_import(name[level:], package, level)
           ^^^^^^^^^^^^^^^^^^^^^^^^^^^^^^^^^^^^^^^^^^^^^^^^^^^^
  File "<frozen importlib._bootstrap>", line 1204, in _gcd_import
  File "<frozen importlib._bootstrap>", line 1176, in _find_and_load
  File "<frozen importlib._bootstrap>", line 1147, in _find_and_load_unlocked
  File "<frozen importlib._bootstrap>", line 690, in _load_unlocked
  File "<frozen importlib._bootstrap_external>", line 940, in exec_module
  File "<frozen importlib._bootstrap>", line 241, in _call_with_frames_removed
  File "/Users/boussastevejunior/Desktop/Dev/Personal/FiberMap/FiberMap/api/urls.py", line 5, in <module>
    from .views import hello
ImportError: cannot import name 'hello' from 'api.views' (/Users/boussastevejunior/Desktop/Dev/Personal/FiberMap/FiberMap/api/views/__init__.py)

During handling of the above exception, another exception occurred:

Traceback (most recent call last):
  File "/Library/Frameworks/Python.framework/Versions/3.11/lib/python3.11/threading.py", line 1045, in _bootstrap_inner
    self.run()
  File "/Library/Frameworks/Python.framework/Versions/3.11/lib/python3.11/threading.py", line 982, in run
    self._target(*self._args, **self._kwargs)
  File "/Library/Frameworks/Python.framework/Versions/3.11/lib/python3.11/site-packages/django/utils/autoreload.py", line 64, in wrapper
    fn(*args, **kwargs)
  File "/Library/Frameworks/Python.framework/Versions/3.11/lib/python3.11/site-packages/django/core/management/commands/runserver.py", line 134, in inner_run
    self.check(**check_kwargs)
  File "/Library/Frameworks/Python.framework/Versions/3.11/lib/python3.11/site-packages/django/core/management/base.py", line 492, in check
    all_issues = checks.run_checks(
                 ^^^^^^^^^^^^^^^^^^
  File "/Library/Frameworks/Python.framework/Versions/3.11/lib/python3.11/site-packages/django/core/checks/registry.py", line 89, in run_checks
    new_errors = check(app_configs=app_configs, databases=databases)
                 ^^^^^^^^^^^^^^^^^^^^^^^^^^^^^^^^^^^^^^^^^^^^^^^^^^^
  File "/Library/Frameworks/Python.framework/Versions/3.11/lib/python3.11/site-packages/django/core/checks/urls.py", line 138, in check_custom_error_handlers
    path = getattr(resolver.urlconf_module, "handler%s" % status_code)
                   ^^^^^^^^^^^^^^^^^^^^^^^
  File "/Library/Frameworks/Python.framework/Versions/3.11/lib/python3.11/site-packages/django/utils/functional.py", line 47, in __get__
    res = instance.__dict__[self.name] = self.func(instance)
                                         ^^^^^^^^^^^^^^^^^^^
  File "/Library/Frameworks/Python.framework/Versions/3.11/lib/python3.11/site-packages/django/urls/resolvers.py", line 711, in urlconf_module
    return import_module(self.urlconf_name)
           ^^^^^^^^^^^^^^^^^^^^^^^^^^^^^^^^
  File "/Library/Frameworks/Python.framework/Versions/3.11/lib/python3.11/importlib/__init__.py", line 126, in import_module
    return _bootstrap._gcd_import(name[level:], package, level)
           ^^^^^^^^^^^^^^^^^^^^^^^^^^^^^^^^^^^^^^^^^^^^^^^^^^^^
  File "<frozen importlib._bootstrap>", line 1204, in _gcd_import
  File "<frozen importlib._bootstrap>", line 1176, in _find_and_load
  File "<frozen importlib._bootstrap>", line 1147, in _find_and_load_unlocked
  File "<frozen importlib._bootstrap>", line 690, in _load_unlocked
  File "<frozen importlib._bootstrap_external>", line 940, in exec_module
  File "<frozen importlib._bootstrap>", line 241, in _call_with_frames_removed
  File "/Users/boussastevejunior/Desktop/Dev/Personal/FiberMap/FiberMap/FiberMap/urls.py", line 13, in <module>
    path('api/', include('api.urls')),
                 ^^^^^^^^^^^^^^^^^^^
  File "/Library/Frameworks/Python.framework/Versions/3.11/lib/python3.11/site-packages/django/urls/conf.py", line 39, in include
    urlconf_module = import_module(urlconf_module)
                     ^^^^^^^^^^^^^^^^^^^^^^^^^^^^^
  File "/Library/Frameworks/Python.framework/Versions/3.11/lib/python3.11/importlib/__init__.py", line 126, in import_module
    return _bootstrap._gcd_import(name[level:], package, level)
           ^^^^^^^^^^^^^^^^^^^^^^^^^^^^^^^^^^^^^^^^^^^^^^^^^^^^
  File "<frozen importlib._bootstrap>", line 1204, in _gcd_import
  File "<frozen importlib._bootstrap>", line 1176, in _find_and_load
  File "<frozen importlib._bootstrap>", line 1147, in _find_and_load_unlocked
  File "<frozen importlib._bootstrap>", line 690, in _load_unlocked
  File "<frozen importlib._bootstrap_external>", line 940, in exec_module
  File "<frozen importlib._bootstrap>", line 241, in _call_with_frames_removed
  File "/Users/boussastevejunior/Desktop/Dev/Personal/FiberMap/FiberMap/api/urls.py", line 5, in <module>
    from .views import hello
ImportError: cannot import name 'hello' from 'api.views' (/Users/boussastevejunior/Desktop/Dev/Personal/FiberMap/FiberMap/api/views/__init__.py)
/Users/boussastevejunior/Desktop/Dev/Personal/FiberMap/FiberMap/api/urls.py changed, reloading.
Performing system checks...

Watching for file changes with StatReloader
Exception in thread django-main-thread:
Traceback (most recent call last):
  File "/Library/Frameworks/Python.framework/Versions/3.11/lib/python3.11/site-packages/django/core/checks/urls.py", line 136, in check_custom_error_handlers
    handler = resolver.resolve_error_handler(status_code)
              ^^^^^^^^^^^^^^^^^^^^^^^^^^^^^^^^^^^^^^^^^^^
  File "/Library/Frameworks/Python.framework/Versions/3.11/lib/python3.11/site-packages/django/urls/resolvers.py", line 732, in resolve_error_handler
    callback = getattr(self.urlconf_module, "handler%s" % view_type, None)
                       ^^^^^^^^^^^^^^^^^^^
  File "/Library/Frameworks/Python.framework/Versions/3.11/lib/python3.11/site-packages/django/utils/functional.py", line 47, in __get__
    res = instance.__dict__[self.name] = self.func(instance)
                                         ^^^^^^^^^^^^^^^^^^^
  File "/Library/Frameworks/Python.framework/Versions/3.11/lib/python3.11/site-packages/django/urls/resolvers.py", line 711, in urlconf_module
    return import_module(self.urlconf_name)
           ^^^^^^^^^^^^^^^^^^^^^^^^^^^^^^^^
  File "/Library/Frameworks/Python.framework/Versions/3.11/lib/python3.11/importlib/__init__.py", line 126, in import_module
    return _bootstrap._gcd_import(name[level:], package, level)
           ^^^^^^^^^^^^^^^^^^^^^^^^^^^^^^^^^^^^^^^^^^^^^^^^^^^^
  File "<frozen importlib._bootstrap>", line 1204, in _gcd_import
  File "<frozen importlib._bootstrap>", line 1176, in _find_and_load
  File "<frozen importlib._bootstrap>", line 1147, in _find_and_load_unlocked
  File "<frozen importlib._bootstrap>", line 690, in _load_unlocked
  File "<frozen importlib._bootstrap_external>", line 940, in exec_module
  File "<frozen importlib._bootstrap>", line 241, in _call_with_frames_removed
  File "/Users/boussastevejunior/Desktop/Dev/Personal/FiberMap/FiberMap/FiberMap/urls.py", line 13, in <module>
    path('api/', include('api.urls')),
                 ^^^^^^^^^^^^^^^^^^^
  File "/Library/Frameworks/Python.framework/Versions/3.11/lib/python3.11/site-packages/django/urls/conf.py", line 39, in include
    urlconf_module = import_module(urlconf_module)
                     ^^^^^^^^^^^^^^^^^^^^^^^^^^^^^
  File "/Library/Frameworks/Python.framework/Versions/3.11/lib/python3.11/importlib/__init__.py", line 126, in import_module
    return _bootstrap._gcd_import(name[level:], package, level)
           ^^^^^^^^^^^^^^^^^^^^^^^^^^^^^^^^^^^^^^^^^^^^^^^^^^^^
  File "<frozen importlib._bootstrap>", line 1204, in _gcd_import
  File "<frozen importlib._bootstrap>", line 1176, in _find_and_load
  File "<frozen importlib._bootstrap>", line 1147, in _find_and_load_unlocked
  File "<frozen importlib._bootstrap>", line 690, in _load_unlocked
  File "<frozen importlib._bootstrap_external>", line 940, in exec_module
  File "<frozen importlib._bootstrap>", line 241, in _call_with_frames_removed
  File "/Users/boussastevejunior/Desktop/Dev/Personal/FiberMap/FiberMap/api/urls.py", line 5, in <module>
    from .views import hello
ImportError: cannot import name 'hello' from 'api.views' (/Users/boussastevejunior/Desktop/Dev/Personal/FiberMap/FiberMap/api/views/__init__.py)

During handling of the above exception, another exception occurred:

Traceback (most recent call last):
  File "/Library/Frameworks/Python.framework/Versions/3.11/lib/python3.11/threading.py", line 1045, in _bootstrap_inner
    self.run()
  File "/Library/Frameworks/Python.framework/Versions/3.11/lib/python3.11/threading.py", line 982, in run
    self._target(*self._args, **self._kwargs)
  File "/Library/Frameworks/Python.framework/Versions/3.11/lib/python3.11/site-packages/django/utils/autoreload.py", line 64, in wrapper
    fn(*args, **kwargs)
  File "/Library/Frameworks/Python.framework/Versions/3.11/lib/python3.11/site-packages/django/core/management/commands/runserver.py", line 134, in inner_run
    self.check(**check_kwargs)
  File "/Library/Frameworks/Python.framework/Versions/3.11/lib/python3.11/site-packages/django/core/management/base.py", line 492, in check
    all_issues = checks.run_checks(
                 ^^^^^^^^^^^^^^^^^^
  File "/Library/Frameworks/Python.framework/Versions/3.11/lib/python3.11/site-packages/django/core/checks/registry.py", line 89, in run_checks
    new_errors = check(app_configs=app_configs, databases=databases)
                 ^^^^^^^^^^^^^^^^^^^^^^^^^^^^^^^^^^^^^^^^^^^^^^^^^^^
  File "/Library/Frameworks/Python.framework/Versions/3.11/lib/python3.11/site-packages/django/core/checks/urls.py", line 138, in check_custom_error_handlers
    path = getattr(resolver.urlconf_module, "handler%s" % status_code)
                   ^^^^^^^^^^^^^^^^^^^^^^^
  File "/Library/Frameworks/Python.framework/Versions/3.11/lib/python3.11/site-packages/django/utils/functional.py", line 47, in __get__
    res = instance.__dict__[self.name] = self.func(instance)
                                         ^^^^^^^^^^^^^^^^^^^
  File "/Library/Frameworks/Python.framework/Versions/3.11/lib/python3.11/site-packages/django/urls/resolvers.py", line 711, in urlconf_module
    return import_module(self.urlconf_name)
           ^^^^^^^^^^^^^^^^^^^^^^^^^^^^^^^^
  File "/Library/Frameworks/Python.framework/Versions/3.11/lib/python3.11/importlib/__init__.py", line 126, in import_module
    return _bootstrap._gcd_import(name[level:], package, level)
           ^^^^^^^^^^^^^^^^^^^^^^^^^^^^^^^^^^^^^^^^^^^^^^^^^^^^
  File "<frozen importlib._bootstrap>", line 1204, in _gcd_import
  File "<frozen importlib._bootstrap>", line 1176, in _find_and_load
  File "<frozen importlib._bootstrap>", line 1147, in _find_and_load_unlocked
  File "<frozen importlib._bootstrap>", line 690, in _load_unlocked
  File "<frozen importlib._bootstrap_external>", line 940, in exec_module
  File "<frozen importlib._bootstrap>", line 241, in _call_with_frames_removed
  File "/Users/boussastevejunior/Desktop/Dev/Personal/FiberMap/FiberMap/FiberMap/urls.py", line 13, in <module>
    path('api/', include('api.urls')),
                 ^^^^^^^^^^^^^^^^^^^
  File "/Library/Frameworks/Python.framework/Versions/3.11/lib/python3.11/site-packages/django/urls/conf.py", line 39, in include
    urlconf_module = import_module(urlconf_module)
                     ^^^^^^^^^^^^^^^^^^^^^^^^^^^^^
  File "/Library/Frameworks/Python.framework/Versions/3.11/lib/python3.11/importlib/__init__.py", line 126, in import_module
    return _bootstrap._gcd_import(name[level:], package, level)
           ^^^^^^^^^^^^^^^^^^^^^^^^^^^^^^^^^^^^^^^^^^^^^^^^^^^^
  File "<frozen importlib._bootstrap>", line 1204, in _gcd_import
  File "<frozen importlib._bootstrap>", line 1176, in _find_and_load
  File "<frozen importlib._bootstrap>", line 1147, in _find_and_load_unlocked
  File "<frozen importlib._bootstrap>", line 690, in _load_unlocked
  File "<frozen importlib._bootstrap_external>", line 940, in exec_module
  File "<frozen importlib._bootstrap>", line 241, in _call_with_frames_removed
  File "/Users/boussastevejunior/Desktop/Dev/Personal/FiberMap/FiberMap/api/urls.py", line 5, in <module>
    from .views import hello
ImportError: cannot import name 'hello' from 'api.views' (/Users/boussastevejunior/Desktop/Dev/Personal/FiberMap/FiberMap/api/views/__init__.py)
/Users/boussastevejunior/Desktop/Dev/Personal/FiberMap/FiberMap/api/views/__init__.py changed, reloading.
Performing system checks...

Watching for file changes with StatReloader
Exception in thread django-main-thread:
Traceback (most recent call last):
  File "/Library/Frameworks/Python.framework/Versions/3.11/lib/python3.11/site-packages/django/core/checks/urls.py", line 136, in check_custom_error_handlers
    handler = resolver.resolve_error_handler(status_code)
              ^^^^^^^^^^^^^^^^^^^^^^^^^^^^^^^^^^^^^^^^^^^
  File "/Library/Frameworks/Python.framework/Versions/3.11/lib/python3.11/site-packages/django/urls/resolvers.py", line 732, in resolve_error_handler
    callback = getattr(self.urlconf_module, "handler%s" % view_type, None)
                       ^^^^^^^^^^^^^^^^^^^
  File "/Library/Frameworks/Python.framework/Versions/3.11/lib/python3.11/site-packages/django/utils/functional.py", line 47, in __get__
    res = instance.__dict__[self.name] = self.func(instance)
                                         ^^^^^^^^^^^^^^^^^^^
  File "/Library/Frameworks/Python.framework/Versions/3.11/lib/python3.11/site-packages/django/urls/resolvers.py", line 711, in urlconf_module
    return import_module(self.urlconf_name)
           ^^^^^^^^^^^^^^^^^^^^^^^^^^^^^^^^
  File "/Library/Frameworks/Python.framework/Versions/3.11/lib/python3.11/importlib/__init__.py", line 126, in import_module
    return _bootstrap._gcd_import(name[level:], package, level)
           ^^^^^^^^^^^^^^^^^^^^^^^^^^^^^^^^^^^^^^^^^^^^^^^^^^^^
  File "<frozen importlib._bootstrap>", line 1204, in _gcd_import
  File "<frozen importlib._bootstrap>", line 1176, in _find_and_load
  File "<frozen importlib._bootstrap>", line 1147, in _find_and_load_unlocked
  File "<frozen importlib._bootstrap>", line 690, in _load_unlocked
  File "<frozen importlib._bootstrap_external>", line 940, in exec_module
  File "<frozen importlib._bootstrap>", line 241, in _call_with_frames_removed
  File "/Users/boussastevejunior/Desktop/Dev/Personal/FiberMap/FiberMap/FiberMap/urls.py", line 13, in <module>
    path('api/', include('api.urls')),
                 ^^^^^^^^^^^^^^^^^^^
  File "/Library/Frameworks/Python.framework/Versions/3.11/lib/python3.11/site-packages/django/urls/conf.py", line 39, in include
    urlconf_module = import_module(urlconf_module)
                     ^^^^^^^^^^^^^^^^^^^^^^^^^^^^^
  File "/Library/Frameworks/Python.framework/Versions/3.11/lib/python3.11/importlib/__init__.py", line 126, in import_module
    return _bootstrap._gcd_import(name[level:], package, level)
           ^^^^^^^^^^^^^^^^^^^^^^^^^^^^^^^^^^^^^^^^^^^^^^^^^^^^
  File "<frozen importlib._bootstrap>", line 1204, in _gcd_import
  File "<frozen importlib._bootstrap>", line 1176, in _find_and_load
  File "<frozen importlib._bootstrap>", line 1147, in _find_and_load_unlocked
  File "<frozen importlib._bootstrap>", line 690, in _load_unlocked
  File "<frozen importlib._bootstrap_external>", line 940, in exec_module
  File "<frozen importlib._bootstrap>", line 241, in _call_with_frames_removed
  File "/Users/boussastevejunior/Desktop/Dev/Personal/FiberMap/FiberMap/api/urls.py", line 5, in <module>
    from .views import hello
  File "/Users/boussastevejunior/Desktop/Dev/Personal/FiberMap/FiberMap/api/views/__init__.py", line 10, in <module>
    from ..views import hello
ImportError: cannot import name 'hello' from partially initialized module 'api.views' (most likely due to a circular import) (/Users/boussastevejunior/Desktop/Dev/Personal/FiberMap/FiberMap/api/views/__init__.py)

During handling of the above exception, another exception occurred:

Traceback (most recent call last):
  File "/Library/Frameworks/Python.framework/Versions/3.11/lib/python3.11/threading.py", line 1045, in _bootstrap_inner
    self.run()
  File "/Library/Frameworks/Python.framework/Versions/3.11/lib/python3.11/threading.py", line 982, in run
    self._target(*self._args, **self._kwargs)
  File "/Library/Frameworks/Python.framework/Versions/3.11/lib/python3.11/site-packages/django/utils/autoreload.py", line 64, in wrapper
    fn(*args, **kwargs)
  File "/Library/Frameworks/Python.framework/Versions/3.11/lib/python3.11/site-packages/django/core/management/commands/runserver.py", line 134, in inner_run
    self.check(**check_kwargs)
  File "/Library/Frameworks/Python.framework/Versions/3.11/lib/python3.11/site-packages/django/core/management/base.py", line 492, in check
    all_issues = checks.run_checks(
                 ^^^^^^^^^^^^^^^^^^
  File "/Library/Frameworks/Python.framework/Versions/3.11/lib/python3.11/site-packages/django/core/checks/registry.py", line 89, in run_checks
    new_errors = check(app_configs=app_configs, databases=databases)
                 ^^^^^^^^^^^^^^^^^^^^^^^^^^^^^^^^^^^^^^^^^^^^^^^^^^^
  File "/Library/Frameworks/Python.framework/Versions/3.11/lib/python3.11/site-packages/django/core/checks/urls.py", line 138, in check_custom_error_handlers
    path = getattr(resolver.urlconf_module, "handler%s" % status_code)
                   ^^^^^^^^^^^^^^^^^^^^^^^
  File "/Library/Frameworks/Python.framework/Versions/3.11/lib/python3.11/site-packages/django/utils/functional.py", line 47, in __get__
    res = instance.__dict__[self.name] = self.func(instance)
                                         ^^^^^^^^^^^^^^^^^^^
  File "/Library/Frameworks/Python.framework/Versions/3.11/lib/python3.11/site-packages/django/urls/resolvers.py", line 711, in urlconf_module
    return import_module(self.urlconf_name)
           ^^^^^^^^^^^^^^^^^^^^^^^^^^^^^^^^
  File "/Library/Frameworks/Python.framework/Versions/3.11/lib/python3.11/importlib/__init__.py", line 126, in import_module
    return _bootstrap._gcd_import(name[level:], package, level)
           ^^^^^^^^^^^^^^^^^^^^^^^^^^^^^^^^^^^^^^^^^^^^^^^^^^^^
  File "<frozen importlib._bootstrap>", line 1204, in _gcd_import
  File "<frozen importlib._bootstrap>", line 1176, in _find_and_load
  File "<frozen importlib._bootstrap>", line 1147, in _find_and_load_unlocked
  File "<frozen importlib._bootstrap>", line 690, in _load_unlocked
  File "<frozen importlib._bootstrap_external>", line 940, in exec_module
  File "<frozen importlib._bootstrap>", line 241, in _call_with_frames_removed
  File "/Users/boussastevejunior/Desktop/Dev/Personal/FiberMap/FiberMap/FiberMap/urls.py", line 13, in <module>
    path('api/', include('api.urls')),
                 ^^^^^^^^^^^^^^^^^^^
  File "/Library/Frameworks/Python.framework/Versions/3.11/lib/python3.11/site-packages/django/urls/conf.py", line 39, in include
    urlconf_module = import_module(urlconf_module)
                     ^^^^^^^^^^^^^^^^^^^^^^^^^^^^^
  File "/Library/Frameworks/Python.framework/Versions/3.11/lib/python3.11/importlib/__init__.py", line 126, in import_module
    return _bootstrap._gcd_import(name[level:], package, level)
           ^^^^^^^^^^^^^^^^^^^^^^^^^^^^^^^^^^^^^^^^^^^^^^^^^^^^
  File "<frozen importlib._bootstrap>", line 1204, in _gcd_import
  File "<frozen importlib._bootstrap>", line 1176, in _find_and_load
  File "<frozen importlib._bootstrap>", line 1147, in _find_and_load_unlocked
  File "<frozen importlib._bootstrap>", line 690, in _load_unlocked
  File "<frozen importlib._bootstrap_external>", line 940, in exec_module
  File "<frozen importlib._bootstrap>", line 241, in _call_with_frames_removed
  File "/Users/boussastevejunior/Desktop/Dev/Personal/FiberMap/FiberMap/api/urls.py", line 5, in <module>
    from .views import hello
  File "/Users/boussastevejunior/Desktop/Dev/Personal/FiberMap/FiberMap/api/views/__init__.py", line 10, in <module>
    from ..views import hello
ImportError: cannot import name 'hello' from partially initialized module 'api.views' (most likely due to a circular import) (/Users/boussastevejunior/Desktop/Dev/Personal/FiberMap/FiberMap/api/views/__init__.py)
/Users/boussastevejunior/Desktop/Dev/Personal/FiberMap/FiberMap/api/views/__init__.py changed, reloading.
Performing system checks...

Watching for file changes with StatReloader
[27/Jul/2025 09:06:08] "GET /api/hello/ HTTP/1.1" 200 335
[27/Jul/2025 09:06:57] "POST /api/auth/login/ HTTP/1.1" 200 359
[27/Jul/2025 09:07:32] "GET /api/liaisons/ HTTP/1.1" 200 2388
[27/Jul/2025 09:07:45] "GET /api/map/liaisons/ HTTP/1.1" 200 692
[27/Jul/2025 09:07:56] "GET /api/coupures/ HTTP/1.1" 200 1155
[27/Jul/2025 09:08:33] "GET /api/hello/ HTTP/1.1" 200 335
[27/Jul/2025 09:08:33] "POST /api/auth/login/ HTTP/1.1" 200 359
[27/Jul/2025 09:08:33] "GET /api/liaisons/ HTTP/1.1" 200 2388
[27/Jul/2025 09:08:33] "GET /api/clients/ HTTP/1.1" 200 833
/Library/Frameworks/Python.framework/Versions/3.11/lib/python3.11/site-packages/rest_framework/pagination.py:207: UnorderedObjectListWarning: Pagination may yield inconsistent results with an unordered object_list: <class 'api.models.TypeLiaison'> QuerySet.
  paginator = self.django_paginator_class(queryset, page_size)
[27/Jul/2025 09:08:33] "GET /api/types-liaisons/ HTTP/1.1" 200 284
[27/Jul/2025 09:08:33] "GET /api/points-dynamiques/ HTTP/1.1" 200 2662
[27/Jul/2025 09:08:34] "GET /api/interventions/ HTTP/1.1" 200 2961
[27/Jul/2025 09:08:34] "GET /api/coupures/ HTTP/1.1" 200 1155
[27/Jul/2025 09:08:34] "GET /api/notifications/ HTTP/1.1" 200 624
[27/Jul/2025 09:08:34] "GET /api/map/liaisons/ HTTP/1.1" 200 692
[27/Jul/2025 09:08:34] "GET /api/map/points-dynamiques/ HTTP/1.1" 200 1748
[27/Jul/2025 09:08:34] "GET /api/liaisons/ HTTP/1.1" 200 2388
[27/Jul/2025 09:08:34] "GET /api/map/trace/dd6bc80b-fe61-4d46-9e96-a1cdc29927ee/ HTTP/1.1" 200 620
[27/Jul/2025 09:08:34] "GET /api/coupures/actives/ HTTP/1.1" 200 1105
/Users/boussastevejunior/Desktop/Dev/Personal/FiberMap/FiberMap/api/urls.py changed, reloading.
Performing system checks...

System check identified no issues (0 silenced).
July 27, 2025 - 09:05:49
Django version 5.2.4, using settings 'FiberMap.settings'
Starting development server at http://127.0.0.1:8000/
Quit the server with CONTROL-C.

WARNING: This is a development server. Do not use it in a production setting. Use a production WSGI or ASGI server instead.
For more information on production servers see: https://docs.djangoproject.com/en/5.2/howto/deployment/
Watching for file changes with StatReloader
Exception in thread django-main-thread:
Traceback (most recent call last):
  File "/Library/Frameworks/Python.framework/Versions/3.11/lib/python3.11/threading.py", line 1045, in _bootstrap_inner
    self.run()
  File "/Library/Frameworks/Python.framework/Versions/3.11/lib/python3.11/threading.py", line 982, in run
    self._target(*self._args, **self._kwargs)
  File "/Library/Frameworks/Python.framework/Versions/3.11/lib/python3.11/site-packages/django/utils/autoreload.py", line 64, in wrapper
    fn(*args, **kwargs)
  File "/Library/Frameworks/Python.framework/Versions/3.11/lib/python3.11/site-packages/django/core/management/commands/runserver.py", line 134, in inner_run
    self.check(**check_kwargs)
  File "/Library/Frameworks/Python.framework/Versions/3.11/lib/python3.11/site-packages/django/core/management/base.py", line 492, in check
    all_issues = checks.run_checks(
                 ^^^^^^^^^^^^^^^^^^
  File "/Library/Frameworks/Python.framework/Versions/3.11/lib/python3.11/site-packages/django/core/checks/registry.py", line 89, in run_checks
    new_errors = check(app_configs=app_configs, databases=databases)
                 ^^^^^^^^^^^^^^^^^^^^^^^^^^^^^^^^^^^^^^^^^^^^^^^^^^^
  File "/Library/Frameworks/Python.framework/Versions/3.11/lib/python3.11/site-packages/django/core/checks/urls.py", line 136, in check_custom_error_handlers
    handler = resolver.resolve_error_handler(status_code)
              ^^^^^^^^^^^^^^^^^^^^^^^^^^^^^^^^^^^^^^^^^^^
  File "/Library/Frameworks/Python.framework/Versions/3.11/lib/python3.11/site-packages/django/urls/resolvers.py", line 732, in resolve_error_handler
    callback = getattr(self.urlconf_module, "handler%s" % view_type, None)
                       ^^^^^^^^^^^^^^^^^^^
  File "/Library/Frameworks/Python.framework/Versions/3.11/lib/python3.11/site-packages/django/utils/functional.py", line 47, in __get__
    res = instance.__dict__[self.name] = self.func(instance)
                                         ^^^^^^^^^^^^^^^^^^^
  File "/Library/Frameworks/Python.framework/Versions/3.11/lib/python3.11/site-packages/django/urls/resolvers.py", line 711, in urlconf_module
    return import_module(self.urlconf_name)
           ^^^^^^^^^^^^^^^^^^^^^^^^^^^^^^^^
  File "/Library/Frameworks/Python.framework/Versions/3.11/lib/python3.11/importlib/__init__.py", line 126, in import_module
    return _bootstrap._gcd_import(name[level:], package, level)
           ^^^^^^^^^^^^^^^^^^^^^^^^^^^^^^^^^^^^^^^^^^^^^^^^^^^^
  File "<frozen importlib._bootstrap>", line 1204, in _gcd_import
  File "<frozen importlib._bootstrap>", line 1176, in _find_and_load
  File "<frozen importlib._bootstrap>", line 1147, in _find_and_load_unlocked
  File "<frozen importlib._bootstrap>", line 690, in _load_unlocked
  File "<frozen importlib._bootstrap_external>", line 940, in exec_module
  File "<frozen importlib._bootstrap>", line 241, in _call_with_frames_removed
  File "/Users/boussastevejunior/Desktop/Dev/Personal/FiberMap/FiberMap/FiberMap/urls.py", line 13, in <module>
    path('api/', include('api.urls')),
                 ^^^^^^^^^^^^^^^^^^^
  File "/Library/Frameworks/Python.framework/Versions/3.11/lib/python3.11/site-packages/django/urls/conf.py", line 39, in include
    urlconf_module = import_module(urlconf_module)
                     ^^^^^^^^^^^^^^^^^^^^^^^^^^^^^
  File "/Library/Frameworks/Python.framework/Versions/3.11/lib/python3.11/importlib/__init__.py", line 126, in import_module
    return _bootstrap._gcd_import(name[level:], package, level)
           ^^^^^^^^^^^^^^^^^^^^^^^^^^^^^^^^^^^^^^^^^^^^^^^^^^^^
  File "<frozen importlib._bootstrap>", line 1204, in _gcd_import
  File "<frozen importlib._bootstrap>", line 1176, in _find_and_load
  File "<frozen importlib._bootstrap>", line 1147, in _find_and_load_unlocked
  File "<frozen importlib._bootstrap>", line 690, in _load_unlocked
  File "<frozen importlib._bootstrap_external>", line 940, in exec_module
  File "<frozen importlib._bootstrap>", line 241, in _call_with_frames_removed
  File "/Users/boussastevejunior/Desktop/Dev/Personal/FiberMap/FiberMap/api/urls.py", line 33, in <module>
    router.register(r'users', NotificationViewSet, basename='user-notifications')
                              ^^^^^^^^^^^^^^^^^^^
NameError: name 'NotificationViewSet' is not defined
/Users/boussastevejunior/Desktop/Dev/Personal/FiberMap/FiberMap/api/urls.py changed, reloading.
Performing system checks...

Watching for file changes with StatReloader
